Workbook

Sheet Hướng dẫn
A1: HƯỚNG DẪN DÙNG FILE NÀY
A3: File Excel này là bản thực thi của kịch bản test trải nghiệm khách hàng (nguồn: KICHBAN_TEST_KHACH_HANG_HealthyAI.md). Bạn cầm điện thoại, làm theo từng kịch bản như một khách hàng thật và ghi kết quả ngay trong file.
A5: CÁCH DÙNG
A6: 1. Mở sheet “Kịch bản test”. Mỗi dòng là một kịch bản (KB-xx) — đúng những gì Quỳnh, khách hàng duy nhất của bộ kịch bản này, sẽ làm.
A7: 2. Đọc cột “Bạn đang ở” (nếu có) → làm theo cột “Bạn làm” → đối chiếu với cột “Bạn sẽ thấy”.
A8: 3. Nếu kết quả khác với cột “Đáng ngờ nếu” → chọn “Không đạt” ở cột KQ, chụp ảnh màn hình và ghi lại vào cột “Ảnh chụp / Ghi chú”.
A9: 4. Cột KQ có sẵn danh sách chọn (Đạt / Không đạt / Chưa test được / Không áp dụng) và tự đổi màu xanh–đỏ theo kết quả.
A10: 5. Sheet “Tổng kết” tự tính tiến độ. Sheet “Không phải lỗi” liệt kê những điều trông như lỗi nhưng là chủ ý — đọc trước khi báo lỗi.
A11: 6. Mỗi kịch bản test trọn vẹn rồi mới sang kịch bản khác. Bị kẹt thì ghi lại rồi đi tiếp, đừng cố sửa.
A13: Lưu ý về bản cài đang test: app cài bằng APK debug (com.healthyai.app, versionName 1.0.0). Kịch bản KB-57…KB-61 nói về widget màn hình chính “Sức khỏe hôm nay” — widget cũ (tiến độ thói quen) sẽ biến mất sau khi cài đè, bạn cần thêm lại widget mới từ danh sách Widgets.
A15: 1. Đọc gì trước khi bắt đầu
A16: 1.1. Ba quy tắc khi test theo vai khách hàng
... A88: Nếu tất cả đều Đạt, bạn có thể tự tin bản dựng này dùng được cho người dùng thật. Sau đó dành thời gian còn lại cho hành trình J (màu sắc/vòng đời) và hành trình E (nhắc nhở) — đây là nơi lỗi hay trốn nhất.

Sheet Kịch bản test
A1: STT | B1: Mã | C1: Hành trình | D1: Mức độ | E1: Kịch bản | F1: Bạn đang ở | G1: Bạn làm | H1: Bạn sẽ thấy | I1: Đáng ngờ nếu | J1: Ghi chú khác | K1: KQ | L1: Ảnh chụp / Ghi chú | M1: Ngày test
A2: 1 | B2: KB-01 | C2: Hành trình A — "Ngày đầu tiên của Quỳnh" | D2: Bắt buộc | E2: Mở app lần đầu | F2: vừa cài app xong, chưa từng mở. | G2: bấm icon HealthyAI. | H2: một khoảnh khắc rất ngắn có vòng xoay + chữ "HealthyAI", sau đó là màn Đăng nhập: logo trái tim xanh, chữ "HealthyAI", dòng "Theo dõi & cải thiện thói quen sức khỏe", 2 ô Email / Mật khẩu, nút Đăng nhập (đang mờ), dòng "Chưa có tài khoản? Đăng ký", và nút "Bỏ qua, dùng ở chế độ khách" kèm dòng giải thích nhỏ bên dưới. | I2: app đứng ở vòng xoay quá 5 giây, trắng màn hình, hoặc thoát ra ngay.
A3: 2 | B3: KB-02 | C3: Hành trình A — "Ngày đầu tiên của Quỳnh" | D3: Tùy chọn | E3: Xem mật khẩu đã gõ | G3: gõ mật khẩu, bấm biểu tượng con mắt trong ô Mật khẩu. | H3: mật khẩu hiện thành chữ thường; bấm lần nữa thì trở lại dấu chấm. | I3: nút không phản ứng, hoặc hiện luôn mật khẩu khi chưa bấm.
A4: 3 | B4: KB-03 | C4: Hành trình A — "Ngày đầu tiên của Quỳnh" | D4: Quan trọng | E4: Gõ sai khi đăng nhập | G4: (1) gõ email abc → bấm Đăng nhập. (2) gõ email abc@gmail.com + mật khẩu 123 → bấm Đăng nhập. (3) gõ email đúng + mật khẩu sai → bấm Đăng nhập. | H4: thẻ lỗi đỏ ngay dưới ô mật khẩu, lần lượt: "Email không hợp lệ" → "Mật khẩu phải có ít nhất 6 ký tự" → "Email hoặc mật khẩu không đúng" (hoặc "Không có kết nối mạng, vui lòng thử lại" nếu máy đang offline). Thẻ lỗi có nút X để đóng, và khi bạn gõ lại thì lỗi tự mất. | I4: app đóng im lặng không phản hồi, hoặc báo lỗi kỹ thuật khó hiểu kiểu "Xác thực thất bại (ERROR_...)" khi lỗi là do bạn gõ sai.
A5: 4 | B5: KB-04 | C5: Hành trình A — "Ngày đầu tiên của Quỳnh" | D5: Quan trọng | E5: Tạo tài khoản mới | G5: bấm "Chưa có tài khoản? Đăng ký" → gõ email + mật khẩu → bấm Đăng ký. | H5: nút đổi thành vòng xoay trong lúc chờ, rồi app vào thẳng Trang chủ. Lời chào có 2 dòng: "Chào buổi sáng," và dòng tên màu xanh = phần trước dấu @ của email (ví dụ email quynh.nguyen@gmail.com → hiện quynh.nguyen). | I5: hiện tên người khác, hiện chữ "Alex", hoặc vẫn đứng ở màn Đăng nhập dù đã tạo được tài khoản. | J5: Lưu ý: nếu tài khoản đã tồn tại, app phải báo "Email này đã được đăng ký, hãy đăng nhập".
A6: 5 | B6: KB-05 | C6: Hành trình A — "Ngày đầu tiên của Quỳnh" | D6: Bắt buộc | E6: Vào app không cần tài khoản (như Quỳnh) | G6: ở màn Đăng nhập, bấm "Bỏ qua, dùng ở chế độ khách". | H6: vào thẳng Trang chủ, lời chào chỉ có 1 dòng ("Chào buổi sáng") và không có dòng tên màu xanh nào. | I6: vẫn hiện một dòng tên (nhất là "Alex"), hoặc hiện dấu phẩy treo lơ lửng ở cuối câu chào.
A7: 6 | B7: KB-06 | C7: Hành trình A — "Ngày đầu tiên của Quỳnh" | D7: Quan trọng | E7: Trang chủ khi chưa có gì | F7: Trang chủ, chưa tạo thói quen, chưa cấp quyền gì. | H7: Bạn sẽ thấy, từ trên xuống: ngày hôm nay viết bằng tiếng Việt → lời chào → icon Đăng xuất và avatar xám ở góc phải → thẻ "Tóm tắt sức khỏe" với 3 vòng tròn Bước chân 0.0k / Ngủ 0h 0m / Tim 0 bpm → thẻ xin quyền Health Connect → thẻ nhắc bật thông báo → tiêu đề "Thói quen hôm nay" → thẻ "Thêm thói quen đầu tiên". Thanh dưới cùng có 4 tab: Trang chủ · Thói quen · Ghi chép · Phân tích. | I7: app hiện banner/thẻ lỗi đỏ ngay khi vừa cài (thẻ xin quyền màu xanh là bình thường), hoặc có tab bấm vào là trắng màn hình.
A8: 7 | B8: KB-07 | C8: Hành trình A — "Ngày đầu tiên của Quỳnh" | D8: Bắt buộc | E8: Tạo thói quen đầu tiên | G8: tab Thói quen → bấm nút tròn + (dưới phải) → màn hình mới mở với tiêu đề "Thêm thói quen mới" → gõ tên Uống nước → chọn ô 💧 Uống nước → nhập mục tiêu 2000 → để nguyên Cả ngày và Hàng ngày → bấm "Tạo thói quen". | H8: quay về danh sách, thẻ Uống nước xuất hiện với dòng "0.0L / 2.0L" và nút xanh "Ghi". Đơn vị tự đổi thành ml khi bạn chọn danh mục Uống nước (đơn vị hiển thị ngay bên phải ô mục tiêu). | I8: app giữ nguyên màn thêm thói quen, hoặc báo lỗi dù đã nhập đủ, hoặc thói quen không xuất hiện trong danh sách.
A9: 8 | B9: KB-08 | C9: Hành trình A — "Ngày đầu tiên của Quỳnh" | D9: Quan trọng | E9: Tạo một thói quen cho mỗi danh mục | G9: tạo thêm 4 thói quen theo bảng dưới đây. Tên bạn gõ · Danh mục chọn · Mục tiêu · Buổi Ngủ đủ giấc · 😴 Giấc ngủ · 8 · Tối Chạy bộ buổi sáng · 🏃 Vận động · 30 · Sáng Ăn salad · 🥗 Dinh dưỡng · 500 · Chiều Thiền 15 phút · 🧘 Thiền định · 15 · Sáng | H9: đơn vị tự đổi theo danh mục — Giấc ngủ → giờ, Vận động → phút, Dinh dưỡng → calo, Thiền định → phút. Danh sách có đủ 5 thói quen, mới tạo nằm trên cùng. | I9: đơn vị sai (ví dụ Vận động hiện "ml"), hoặc không chọn được buổi/tần suất.
A10: 9 | B10: KB-09 | C10: Hành trình B — "Một ngày dùng app của Quỳnh" | D10: Bắt buộc | E10: Ghi nhận một lần uống nước | G10: tab Thói quen → bấm nút "Ghi" trên thẻ Uống nước → hộp thoại "Ghi nhận Uống nước" hiện ra với ô số điền sẵn 2000 (không có đuôi .0) → xoá và gõ 1000 → bấm Lưu. | H10: hộp thoại đóng, một dòng chữ nhỏ nổi lên "Đã ghi nhận: Uống nước", và thẻ đổi thành "1.0L / 2.0L". | I10: không có thông báo nào, hoặc tiến độ không đổi, hoặc ô mặc định hiện 2000.0.
A11: 10 | B11: KB-10 | C11: Hành trình B — "Một ngày dùng app của Quỳnh" | D11: Bắt buộc | E11: Ghi đủ và đạt mục tiêu | G11: bấm "Ghi" thêm một lần nữa, nhập 1000, Lưu. | H11: nút "Ghi" biến thành ô xám chữ "Xong", phía trên là dòng xanh "Hoàn thành", và icon tròn bên trái đổi thành dấu ✓. | I11: vẫn cho bấm "Ghi" và tiến độ vượt quá mục tiêu mà không báo gì (ghi lại để đối chiếu, đây là điểm cần thống nhất với nhóm sản phẩm).
A12: 11 | B12: KB-11 | C12: Hành trình B — "Một ngày dùng app của Quỳnh" | D12: Quan trọng | E12: Ghi nhận vận động theo từng lần | G12: ghi 10 phút cho Chạy bộ buổi sáng ba lần. | H12: sau lần 1 thẻ hiện 10 / 30 phút, lần 2 hiện 20 / 30 phút, lần 3 thẻ chuyển hẳn sang "Hoàn thành" + nút "Xong". | I12: phải ghi 1 lần 30 phút mới đạt (tức là app không cộng dồn), hoặc lần ghi sau ghi đè lần trước.
A13: 12 | B13: KB-12 | C13: Hành trình B — "Một ngày dùng app của Quỳnh" | D13: Quan trọng | E13: Lọc thói quen theo buổi | G13: ở tab Thói quen, bấm lần lượt các chip Tất cả · Sáng · Chiều · Tối. | H13: "Sáng" chỉ hiện thói quen đặt Buổi sáng và Cả ngày (ví dụ Uống nước luôn hiện vì để Cả ngày); "Chiều"/"Tối" tương tự; "Tất cả" hiện đủ 5. | I13: chip không đổi trạng thái khi bấm, hoặc lọc ra danh sách trống dù có thói quen đúng buổi.
A14: 13 | B14: KB-13 | C14: Hành trình B — "Một ngày dùng app của Quỳnh" | D14: Quan trọng | E14: Sửa mục tiêu của một thói quen | G14: bấm vào thẻ Chạy bộ buổi sáng → màn "Sửa thói quen" → ô mục tiêu điền sẵn 30 → đổi thành 45 → bấm "Cập nhật". | H14: quay về danh sách, thẻ hiện 30 / 45 phút (không còn "Hoàn thành" vì mục tiêu cao hơn). | I14: ô mục tiêu hiện 30.0, hoặc đổi mục tiêu xong mà danh sách vẫn số cũ.
A15: 14 | B15: KB-14 | C15: Hành trình B — "Một ngày dùng app của Quỳnh" | D15: Tùy chọn | E15: Huỷ giữa đường | G15: bấm "Ghi" trên một thói quen, gõ số khác, rồi bấm Hủy. | H15: hộp thoại đóng, tiến độ không đổi, không có thông báo "Đã ghi nhận". | I15: vẫn ghi nhận dù bạn đã bấm Hủy.
A16: 15 | B16: KB-15 | C16: Hành trình B — "Một ngày dùng app của Quỳnh" | D16: Quan trọng | E16: Xoá một thói quen | G16: bấm vào thẻ Ăn salad → bấm icon thùng rác đỏ ở góc phải trên → đọc hộp thoại "Xóa thói quen?" → bấm Xóa. | H16: hộp thoại nói rõ "Thói quen sẽ bị ẩn khỏi danh sách và không còn được tính vào tiến độ hôm nay. Nhật ký đã ghi vẫn được giữ lại trong máy." → sau khi xoá: dòng chữ "Đã xóa thói quen", quay về danh sách và thẻ đó biến mất khỏi tab Thói quen, khỏi Trang chủ và khỏi widget. | I16: thói quen vẫn còn, hoặc app báo lỗi, hoặc xoá luôn cả nhật ký cũ (kiểm tra bằng tab Phân tích ở KB-53).
A17: 16 | B17: KB-16 | C17: Hành trình B — "Một ngày dùng app của Quỳnh" | D17: Tùy chọn | E17: Đổi ý, không xoá nữa | G17: vào một thói quen → bấm thùng rác → bấm Hủy. | H17: hộp thoại đóng, thói quen còn nguyên, không có thông báo "Đã xóa".
A18: 17 | B18: KB-17 | C18: Hành trình B — "Một ngày dùng app của Quỳnh" | D18: Tùy chọn | E18: Dùng lại tên của thói quen đã xoá | G18: tạo thói quen mới tên Ăn salad (tên vừa xoá ở KB-15) → bấm Tạo. | H18: tạo được bình thường, không báo trùng tên. | I18: báo "Tên thói quen đã tồn tại" cho một thói quen bạn đã xoá.
A19: 18 | B19: KB-18 | C19: Hành trình B — "Một ngày dùng app của Quỳnh" | D19: Quan trọng | E19: Chống trùng tên thói quen | G19: tạo thói quen mới tên uống NƯỚC (khác hoa/thường, có khoảng trắng thừa) rồi bấm Tạo. | H19: hộp thoại "Lỗi" với nội dung "Tên thói quen đã tồn tại", thói quen không được tạo. | I19: tạo được và bạn có 2 thói quen cùng tên (rất dễ ghi nhầm nhật ký về sau).
A20: 19 | B20: KB-19 | C20: Hành trình C — "Quỳnh lỡ tay: gõ sai và thao tác lộn xộn" | D20: Quan trọng | E20: Tạo thói quen khi bỏ trống tên | G20: màn Thêm thói quen → không gõ tên → nhập mục tiêu 100 → bấm Tạo thói quen. | H20: hộp thoại "Lỗi": "Tên thói quen không được để trống", vẫn ở màn thêm thói quen.
A21: 20 | B21: KB-20 | C21: Hành trình C — "Quỳnh lỡ tay: gõ sai và thao tác lộn xộn" | D21: Quan trọng | E21: Mục tiêu không hợp lệ | G21: nhập tên Test mục tiêu, rồi lần lượt thử: để trống mục tiêu → bấm Tạo; nhập 0 → bấm Tạo; (nếu gõ được) nhập -5 → bấm Tạo. | H21: mỗi lần đều báo "Mục tiêu phải là số dương" và không tạo thói quen. | I21: app tạo ra thói quen mục tiêu 0 rồi hiển thị "Hoàn thành" ngay (dấu hiệu tính sai).
A22: 21 | B22: KB-21 | C22: Hành trình C — "Quỳnh lỡ tay: gõ sai và thao tác lộn xộn" | D22: Quan trọng | E22: Ghi nhận khi bỏ trống số lượng | G22: bấm "Ghi" trên một thói quen → xoá trắng ô số lượng → bấm Lưu. | H22: hộp thoại vẫn mở, dòng lỗi đỏ dưới ô nhập: "Vui lòng nhập số lượng"; tiến độ không đổi. | I22: hộp thoại đóng im lặng mà không ghi gì và cũng không báo gì (bạn sẽ tưởng đã ghi thành công).
A23: 22 | B23: KB-22 | C23: Hành trình C — "Quỳnh lỡ tay: gõ sai và thao tác lộn xộn" | D23: Tùy chọn | E23: Ghi nhận bằng chữ | G23: dán/gõ abc vào ô số lượng → Lưu. | H23: lỗi "Số lượng phải là số", hộp thoại vẫn mở.
A24: 23 | B24: KB-23 | C24: Hành trình C — "Quỳnh lỡ tay: gõ sai và thao tác lộn xộn" | D24: Quan trọng | E24: Ghi nhận số 0 hoặc số âm | G24: lần lượt nhập 0 → Lưu; rồi nhập -5 → Lưu. | H24: lỗi "Số lượng phải lớn hơn 0", hộp thoại vẫn mở, tiến độ hôm nay không giảm. | I24: nhập số âm làm tiến độ tụt xuống (lỗi nghiêm trọng về dữ liệu).
A25: 24 | B25: KB-24 | C25: Hành trình C — "Quỳnh lỡ tay: gõ sai và thao tác lộn xộn" | D25: Quan trọng | E25: Bấm Lưu liên tục như người sốt ruột | G25: mở hộp thoại ghi nhận → bấm Lưu thật nhanh nhiều lần; rồi vào màn Sửa thói quen → sửa mục tiêu → bấm "Cập nhật" thật nhanh nhiều lần; cuối cùng ở màn Thêm thói quen mới → bấm "Tạo thói quen" thật nhanh nhiều lần. | H25: hộp thoại ghi nhận đóng ngay sau lần bấm đầu nên không thể ghi trùng; ở hai màn còn lại nút mờ đi và hiện vòng xoay trong lúc lưu, và kết quả chỉ có một thói quen/cập nhật. | I25: tiến độ tăng gấp nhiều lần (ví dụ ghi 1000ml mà thành 5000ml), hoặc danh sách xuất hiện 2 thói quen trùng tên.
A26: 25 | B26: KB-25 | C26: Hành trình C — "Quỳnh lỡ tay: gõ sai và thao tác lộn xộn" | D26: Quan trọng | E26: Xoay màn hình khi đang nhập | G26: (1) Ở màn Sửa thói quen, gõ tên mới nhưng chưa lưu → xoay ngang màn hình. (2) Mở hộp thoại ghi nhận rồi xoay màn hình. | H26: Bạn sẽ thấy (1): nội dung bạn vừa gõ vẫn còn. (2): hộp thoại ghi nhận có thể đóng lại và bạn phải bấm "Ghi" lần nữa — ghi lại nếu điều này làm bạn khó chịu (đây là hiện trạng đã biết, không phải lỗi crash). | I26: app crash, hoặc mất luôn tên/mục tiêu đã gõ ở màn Sửa.
A27: 26 | B27: KB-26 | C27: Hành trình C — "Quỳnh lỡ tay: gõ sai và thao tác lộn xộn" | D27: Quan trọng | E27: Nút Back của điện thoại | G27: ở từng tab bấm Back; ở màn Thêm/Sửa thói quen bấm Back; ở Trang chủ bấm Back. | H27: ở màn Thêm/Sửa → quay về tab Thói quen (và thanh 4 tab dưới cùng ẩn ở màn này); ở một trong 4 tab → về Trang chủ; ở Trang chủ → thoát app. | I27: bấm Back làm app thoát ngay từ tab Phân tích, hoặc quay về màn Đăng nhập dù bạn chưa đăng xuất.
A28: 27 | B28: KB-27 | C28: Hành trình C — "Quỳnh lỡ tay: gõ sai và thao tác lộn xộn" | D28: Quan trọng | E28: Dùng app khi mất mạng hoàn toàn | G28: bật chế độ máy bay → tạo thói quen, ghi nhận, mở Camera, mở Phân tích → sau đó thử đăng nhập/đăng ký. | H28: thói quen/ghi nhận/Phân tích vẫn hoạt động bình thường; chỉ phần đăng nhập báo "Không có kết nối mạng, vui lòng thử lại". | I28: thao tác thói quen bị treo hoặc chậm bất thường khi không có mạng.
A29: 28 | B29: KB-28 | C29: Hành trình D — "Quỳnh muốn số liệu sức khỏe tự hiện" | D29: Quan trọng | E29: Máy chưa cài Health Connect | F29: Trang chủ, máy không có app Health Connect. | G29: bấm "Cài Health Connect" → app mở Google Play. | H29: thẻ "Chưa cài Health Connect" với nút "Cài Health Connect"; 3 chỉ số hiển thị 0; không có banner lỗi đỏ. | I29: app crash, hoặc hiện banner đỏ báo lỗi kỹ thuật.
A30: 29 | B30: KB-29 | C30: Hành trình D — "Quỳnh muốn số liệu sức khỏe tự hiện" | D30: Tùy chọn | E30: Health Connect cần cập nhật | H30: Bạn sẽ thấy (nếu máy ở tình huống này): thẻ "Health Connect cần được cập nhật" + nút "Cập nhật Health Connect".
A31: 30 | B31: KB-30 | C31: Hành trình D — "Quỳnh muốn số liệu sức khỏe tự hiện" | D31: Bắt buộc | E31: Cấp quyền Health Connect | G31: ở Trang chủ, thẻ "Cấp quyền Health Connect" → bấm nút → hộp thoại của Health Connect hiện ra → bật cả 4 quyền (Bước chân, Giấc ngủ, Nhịp tim, Calories) → quay lại app. | H31: thẻ biến mất và số liệu được nạp lại ngay — bạn không cần mở lại app. | I31: thẻ vẫn còn sau khi đã bật đủ 4 quyền (thử rời Trang chủ rồi quay lại; nếu vẫn còn thì ghi lại).
A32: 31 | B32: KB-31 | C32: Hành trình D — "Quỳnh muốn số liệu sức khỏe tự hiện" | D32: Quan trọng | E32: Cố tình cấp thiếu quyền | G32: trong hộp thoại Health Connect, chỉ bật Bước chân và Giấc ngủ, tắt Nhịp tim và Calories → quay lại. | H32: thẻ xin quyền vẫn còn để nhắc bạn; app không crash; không có banner lỗi đỏ. | I32: app crash hoặc màn Trang chủ trắng.
A33: 32 | B33: KB-32 | C33: Hành trình D — "Quỳnh muốn số liệu sức khỏe tự hiện" | D33: Quan trọng | E33: Bơm dữ liệu giả và xem chỉ số | G33: làm theo phụ lục B để bơm steps = 3 500, giấc ngủ = 7 giờ 30 phút, nhịp tim = 72 → sau đó tắt hẳn app rồi mở lại (Cài đặt máy → Ứng dụng → HealthyAI → Buộc dừng, rồi mở app lại). | H33: thẻ "Tóm tắt sức khỏe" hiện Bước chân 3.5k, Ngủ 7h 30m, Tim 72 bpm. | I33: số vẫn là 0 sau khi đã bơm dữ liệu, đã cấp đủ quyền và đã mở lại app (ghi lại giờ bơm dữ liệu + ảnh chụp). | J33: Điểm cần biết trước: màn Trang chủ chỉ đọc lại số liệu khi app được mở lại hoặc khi trạng thái quyền Health Connect vừa thay đổi. Chuyển sang tab khác rồi quay lại Trang chủ không làm số liệu tự đọc lại — nên bạn sẽ thấy số đứng im nếu bơm dữ liệu trong lúc app đang mở (xem mục 5 và mục 6 #11).
A34: 33 | B34: KB-33 | C34: Hành trình D — "Quỳnh muốn số liệu sức khỏe tự hiện" | D34: Tùy chọn | E34: Từ chối quyền Health Connect | G34: ở hộp thoại Health Connect, bấm Từ chối (thử 2 lần). | H34: thẻ xin quyền vẫn hiện, app dùng bình thường với số liệu 0. | I34: bấm Từ chối mà hộp thoại cứ hiện lại liên tục không cho dùng app.
A35: 34 | B35: KB-34 | C35: Hành trình D — "Quỳnh muốn số liệu sức khỏe tự hiện" | D35: Quan trọng | E35: Số liệu có nhớ sau khi tắt app | G35: sau KB-32, tắt hẳn app rồi mở lại. | H35: các chỉ số sức khỏe vẫn hiện (không quay về 0).
A36: 35 | B36: KB-35 | C36: Hành trình D — "Quỳnh muốn số liệu sức khỏe tự hiện" | D36: Tùy chọn | E36: Gợi ý dựa trên dữ liệu Health Connect | H36: nếu chưa đủ dữ liệu, tab Phân tích chỉ hiển thị gợi ý từ nhật ký thói quen của bạn (xem hành trình G) — đây là hiện trạng bình thường, không phải lỗi. | J36: Điều cần biết trước: loại gợi ý này cần dữ liệu nhiều ngày liên tiếp (app tự đồng bộ 6 giờ/lần), nên rất khó thấy trong một buổi test.
A37: 36 | B37: KB-36 | C37: Hành trình E — "Quỳnh không muốn bị làm phiền" | D37: Quan trọng | E37: Bật nhắc nhở hàng ngày | G37: ở Trang chủ, thẻ "Bật nhắc nhở hàng ngày" → bấm "Bật thông báo" → hộp thoại hệ thống → Cho phép. | H37: thẻ biến mất ngay. | I37: thẻ vẫn còn sau khi đã bấm Cho phép (thử rời rồi quay lại Trang chủ).
A38: 37 | B38: KB-37 | C38: Hành trình E — "Quỳnh không muốn bị làm phiền" | D38: Quan trọng | E38: Từ chối quyền thông báo | G38: thẻ "Bật nhắc nhở hàng ngày" → "Bật thông báo" → Từ chối. | H38: thẻ vẫn còn để nhắc lại; app không crash; mọi tính năng khác bình thường.
A39: 38 | B39: KB-38 | C39: Hành trình E — "Quỳnh không muốn bị làm phiền" | D39: Quan trọng | E39: Tắt thông báo ở cài đặt máy | G39: vào Cài đặt máy → Ứng dụng → HealthyAI → Thông báo → tắt → quay lại app. | H39: thẻ đổi thành "Thông báo đang bị tắt" với nút "Mở cài đặt thông báo"; bấm nút này phải mở đúng màn cài đặt thông báo của HealthyAI. | I39: vẫn hiện nút "Bật thông báo" như lúc chưa cấp quyền, hoặc nút mở sai màn hình.
A40: 39 | B40: KB-39 | C40: Hành trình E — "Quỳnh không muốn bị làm phiền" | D40: Tùy chọn | E40: Bật lại thông báo | G40: ở màn cài đặt vừa mở, bật thông báo lại → quay về app. | H40: thẻ nhắc biến mất.
...

Sheet Tổng kết
A1: TỔNG KẾT KẾT QUẢ
A2: Các ô dưới đây tự tính từ cột KQ ở sheet “Kịch bản test” — bạn không cần sửa.
A4: Theo trạng thái
A5: Trạng thái | B5: Số kịch bản
A6: Đạt | B6: =COUNTIF('Kịch bản test'!$K$2:$K$81,"Đạt") -> 0
A7: Không đạt | B7: =COUNTIF('Kịch bản test'!$K$2:$K$81,"Không đạt") -> 0
A8: Chưa test được | B8: =COUNTIF('Kịch bản test'!$K$2:$K$81,"Chưa test được") -> 0
A9: Không áp dụng | B9: =COUNTIF('Kịch bản test'!$K$2:$K$81,"Không áp dụng") -> 0
A10: Chưa có kết quả | B10: =COUNTA('Kịch bản test'!$B$2:$B$81)-SUM(B6:B9) -> 80
A11: Tổng số kịch bản | B11: =COUNTA('Kịch bản test'!$B$2:$B$81) -> 80
A13: Theo mức độ
A14: Mức độ | B14: Tổng | C14: Không đạt | D14: Chưa test
A15: Bắt buộc | B15: =COUNTIF('Kịch bản test'!$D$2:$D$81,"Bắt buộc") -> 10 | C15: =COUNTIFS('Kịch bản test'!$D$2:$D$81,"Bắt buộc",'Kịch bản test'!$K$2:$K$81,"Không đạt") -> 0 | D15: =COUNTIFS('Kịch bản test'!$D$2:$D$81,"Bắt buộc",'Kịch bản test'!$K$2:$K$81,"") -> 10
A16: Quan trọng | B16: =COUNTIF('Kịch bản test'!$D$2:$D$81,"Quan trọng") -> 50 | C16: =COUNTIFS('Kịch bản test'!$D$2:$D$81,"Quan trọng",'Kịch bản test'!$K$2:$K$81,"Không đạt") -> 0 | D16: =COUNTIFS('Kịch bản test'!$D$2:$D$81,"Quan trọng",'Kịch bản test'!$K$2:$K$81,"") -> 50
A17: Tùy chọn | B17: =COUNTIF('Kịch bản test'!$D$2:$D$81,"Tùy chọn") -> 20 | C17: =COUNTIFS('Kịch bản test'!$D$2:$D$81,"Tùy chọn",'Kịch bản test'!$K$2:$K$81,"Không đạt") -> 0 | D17: =COUNTIFS('Kịch bản test'!$D$2:$D$81,"Tùy chọn",'Kịch bản test'!$K$2:$K$81,"") -> 20
A19: Theo hành trình
A20: Hành trình | B20: Tổng | C20: Không đạt | D20: Chưa test
A21: Hành trình A — "Ngày đầu tiên của Quỳnh" | B21: =COUNTIF('Kịch bản test'!$C$2:$C$81,"Hành trình A*") -> 8 | C21: =COUNTIFS('Kịch bản test'!$C$2:$C$81,"Hành trình A*",'Kịch bản test'!$K$2:$K$81,"Không đạt") -> 0 | D21: =COUNTIFS('Kịch bản test'!$C$2:$C$81,"Hành trình A*",'Kịch bản test'!$K$2:$K$81,"") -> 8
A22: Hành trình B — "Một ngày dùng app của Quỳnh" | B22: =COUNTIF('Kịch bản test'!$C$2:$C$81,"Hành trình B*") -> 10 | C22: =COUNTIFS('Kịch bản test'!$C$2:$C$81,"Hành trình B*",'Kịch bản test'!$K$2:$K$81,"Không đạt") -> 0 | D22: =COUNTIFS('Kịch bản test'!$C$2:$C$81,"Hành trình B*",'Kịch bản test'!$K$2:$K$81,"") -> 10
A23: Hành trình C — "Quỳnh lỡ tay: gõ sai và thao tác lộn xộn" | B23: =COUNTIF('Kịch bản test'!$C$2:$C$81,"Hành trình C*") -> 9 | C23: =COUNTIFS('Kịch bản test'!$C$2:$C$81,"Hành trình C*",'Kịch bản test'!$K$2:$K$81,"Không đạt") -> 0 | D23: =COUNTIFS('Kịch bản test'!$C$2:$C$81,"Hành trình C*",'Kịch bản test'!$K$2:$K$81,"") -> 9
A24: Hành trình D — "Quỳnh muốn số liệu sức khỏe tự hiện" | B24: =COUNTIF('Kịch bản test'!$C$2:$C$81,"Hành trình D*") -> 8 | C24: =COUNTIFS('Kịch bản test'!$C$2:$C$81,"Hành trình D*",'Kịch bản test'!$K$2:$K$81,"Không đạt") -> 0 | D24: =COUNTIFS('Kịch bản test'!$C$2:$C$81,"Hành trình D*",'Kịch bản test'!$K$2:$K$81,"") -> 8
A25: Hành trình E — "Quỳnh không muốn bị làm phiền" | B25: =COUNTIF('Kịch bản test'!$C$2:$C$81,"Hành trình E*") -> 6 | C25: =COUNTIFS('Kịch bản test'!$C$2:$C$81,"Hành trình E*",'Kịch bản test'!$K$2:$K$81,"Không đạt") -> 0 | D25: =COUNTIFS('Kịch bản test'!$C$2:$C$81,"Hành trình E*",'Kịch bản test'!$K$2:$K$81,"") -> 6
A26: Hành trình F — "Quỳnh muốn chụp ảnh bữa ăn" | B26: =COUNTIF('Kịch bản test'!$C$2:$C$81,"Hành trình F*") -> 5 | C26: =COUNTIFS('Kịch bản test'!$C$2:$C$81,"Hành trình F*",'Kịch bản test'!$K$2:$K$81,"Không đạt") -> 0 | D26: =COUNTIFS('Kịch bản test'!$C$2:$C$81,"Hành trình F*",'Kịch bản test'!$K$2:$K$81,"") -> 5
A27: Hành trình G — "Quỳnh kiểm tra xem app có thông minh không" | B27: =COUNTIF('Kịch bản test'!$C$2:$C$81,"Hành trình G*") -> 10 | C27: =COUNTIFS('Kịch bản test'!$C$2:$C$81,"Hành trình G*",'Kịch bản test'!$K$2:$K$81,"Không đạt") -> 0 | D27: =COUNTIFS('Kịch bản test'!$C$2:$C$81,"Hành trình G*",'Kịch bản test'!$K$2:$K$81,"") -> 10
A28: Hành trình H — "Quỳnh muốn thấy sức khỏe hôm nay ngay trên màn hình chính" | B28: =COUNTIF('Kịch bản test'!$C$2:$C$81,"Hành trình H*") -> 5 | C28: =COUNTIFS('Kịch bản test'!$C$2:$C$81,"Hành trình H*",'Kịch bản test'!$K$2:$K$81,"Không đạt") -> 0 | D28: =COUNTIFS('Kịch bản test'!$C$2:$C$81,"Hành trình H*",'Kịch bản test'!$K$2:$K$81,"") -> 5
A29: Hành trình I — "Quỳnh kiểm tra tài khoản và dữ liệu" | B29: =COUNTIF('Kịch bản test'!$C$2:$C$81,"Hành trình I*") -> 8 | C29: =COUNTIFS('Kịch bản test'!$C$2:$C$81,"Hành trình I*",'Kịch bản test'!$K$2:$K$81,"Không đạt") -> 0 | D29: =COUNTIFS('Kịch bản test'!$C$2:$C$81,"Hành trình I*",'Kịch bản test'!$K$2:$K$81,"") -> 8
A30: Hành trình J — "Quỳnh soi từng chi tiết: màu, cỡ chữ, vòng đời" | B30: =COUNTIF('Kịch bản test'!$C$2:$C$81,"Hành trình J*") -> 7 | C30: =COUNTIFS('Kịch bản test'!$C$2:$C$81,"Hành trình J*",'Kịch bản test'!$K$2:$K$81,"Không đạt") -> 0 | D30: =COUNTIFS('Kịch bản test'!$C$2:$C$81,"Hành trình J*",'Kịch bản test'!$K$2:$K$81,"") -> 7
A31: Hành trình K — "Quỳnh muốn app tự đếm bước, không cần app nào khác" | B31: =COUNTIF('Kịch bản test'!$C$2:$C$81,"Hành trình K*") -> 4 | C31: =COUNTIFS('Kịch bản test'!$C$2:$C$81,"Hành trình K*",'Kịch bản test'!$K$2:$K$81,"Không đạt") -> 0 | D31: =COUNTIFS('Kịch bản test'!$C$2:$C$81,"Hành trình K*",'Kịch bản test'!$K$2:$K$81,"") -> 4

Sheet Không phải lỗi
A1: ĐỌC TRƯỚC KHI BÁO LỖI — những điều sau là CHỦ Ý, không phải lỗi
A3: 5. Điều KHÔNG phải lỗi (giới hạn đã biết — đừng ghi thành lỗi)
A4: Hiện tượng bạn có thể gặp · Vì sao · Ghi thế nào
A5: Chỉ số sức khỏe = 0 dù máy có Health Connect · Bạn chưa cấp đủ 4 quyền, hoặc máy chưa có dữ liệu · Ghi "chưa cấp quyền/chưa có dữ liệu"
A6: Tab Phân tích gần như trống trong buổi test đầu · Gợi ý theo dữ liệu Health Connect cần nhiều ngày liên tiếp · Ghi "chưa đủ dữ liệu để đánh giá"
A7: Kết quả camera vô nghĩa ("Garden", "Table"…) · Đang chụp ảnh webcam/văn phòng thay vì đồ ăn thật · Không ghi là lỗi
A8: Thẻ "Xu hướng chất lượng giấc ngủ" báo chưa có dữ liệu · Máy/nhà sản xuất không ghi được pha Sâu/Nông/REM · Không ghi là lỗi
A9: Thông báo nhắc nhở chưa đến ngay · Job nhắc nhở chạy theo chu kỳ 24 giờ, hơn nữa chỉ chạy khi pin không yếu · Dùng cách ở phụ lục C để chạy ngay
A10: Không xem được dữ liệu bằng công cụ xem database · Dữ liệu lưu trên máy đã được mã hoá · Không ghi là lỗi
A11: Chế độ khách không được nhớ sau khi tắt hẳn app · Hiện trạng (KB-66) · Ghi thành đề xuất cải tiến
A12: Gỡ app rồi cài lại thì mất dữ liệu · Dữ liệu nằm trên máy, không có tài khoản để khôi phục · Ghi "đúng như thiết kế"
A13: Số liệu sức khỏe không đổi dù vừa có dữ liệu mới trong Health Connect · Trang chủ chỉ đọc lại số liệu khi mở lại app hoặc khi quyền Health Connect vừa thay đổi — chuyển tab qua lại không kích hoạt đọc lại · Mở lại app rồi đo lại; nếu vẫn sai thì ghi lỗi
... A31: 11. Số liệu sức khỏe "đứng im" và không có lời giải thích (KB-32): khi Health Connect có dữ liệu mới, Trang chủ vẫn hiện số cũ cho tới khi bạn tắt hẳn app rồi mở lại; và khi app không đọc được dữ liệu (thiếu quyền, máy chưa có dữ liệu), nó lặng lẽ hiện số 0 thay vì nói "chưa có dữ liệu". Với một khách hàng, "0 bpm" trông giống như app bị lỗi. Hãy ghi lại cảm nhận này để nhóm sản phẩm cân nhắc: tự làm mới số liệu khi mở lại Trang chủ, và phân biệt rõ "0 vì chưa có dữ liệu" với "không đọc được".

Sheet Phụ lục
A1: PHỤ LỤC — dữ liệu, tác vụ nền, từ điển chữ trên màn hình
A3: Phụ lục A — Công thức tạo nhanh từng loại gợi ý AI
A4: Gợi ý AI được tính từ nhật ký ghi trong 7 ngày gần nhất. Bạn không cần chờ nhiều ngày — chỉ cần ghi nhiều lần trong cùng một ngày theo công thức sau:
A5: Gợi ý bạn muốn thấy · Cách tạo · Nội dung sẽ hiện
A6: 🚨 Mức nước nguy hiểm thấp (khẩn cấp) · Thói quen Uống nước 2000ml → ghi 300 ba lần · "Bạn uống trung bình 300ml/ngày…" + nút "Ghi nhận uống nước"
A7: 💧 Uống thêm nước mỗi ngày · Xoá dữ liệu → ghi 1200 một lần · "Lượng nước trung bình của bạn là 1200ml/ngày…", không có nút
A8: ⚠️ Cảnh báo thiếu ngủ nghiêm trọng · Thói quen Ngủ 8 giờ → ghi 5 ba lần · "…ngủ trung bình 5.0 tiếng/đêm…" + nút "Đặt nhắc nhở đi ngủ"
A9: 💤 Cải thiện chất lượng giấc ngủ · Sau khi có 3 lần 5, ghi thêm ba lần 8 · "Chất lượng giấc ngủ của bạn có thể tốt hơn…", không có nút
A10: 🏃 Tăng hoạt động thể chất ngay hôm nay · Thói quen Chạy bộ 30 phút → ghi 10 ba lần · Nói phút và % mục tiêu (không nói "bước") + nút "Ghi nhận vận động"
A11: 🚶 Tăng dần mục tiêu vận động · Tiếp tục ghi thêm hai lần 25 · Chuyển sang mức nhẹ hơn
A12: ✅ Mọi thứ đang rất tốt! · Ghi đủ/vượt mục tiêu đến khi hết cảnh báo (xem KB-53) · "Bạn đang duy trì thói quen rất đều đặn…"
A13: Mẹo cho người test: sau mỗi lần ghi, chỉ cần chuyển sang tab Phân tích — gợi ý cập nhật ngay, không cần chờ.
... A101: Hết tài liệu. Khi test xong, gửi lại mục 8 (bảng theo dõi) + các vấn đề ở mục 7 cho nhóm phát triển.
